Workbook
Name IQ_CH: 110000
Name IQ_CQ: 5000
Name IQ_CY: 10000
Name IQ_DAILY: 500000
Name IQ_FH: 100000
Name IQ_FQ: 500
Name IQ_FY: 1000
Name IQ_LTM: 2000
Name IQ_MONTH: 15000
Name IQ_NTM: 6000
Name IQ_WEEK: 50000
Name IQ_YTD: 3000
Name 슬라이서_COMMODITY: #N/A
Name 슬라이서_COMMODITY1: #N/A
Name 슬라이서_COMMODITY2: #N/A
Name 슬라이서_COUNTRY: #N/A
Name 슬라이서_COUNTRY1: #N/A
Name 슬라이서_COUNTRY2: #N/A

Sheet 광종별
E3: 2024 생산 | F3: 2025 생산(EST.) | G3: 2025 생산(EST.) 계(Rounded) | H3: 2025 광종별 생산(EST.) 국가 점유율(%) | I3: 2025 광종별 생산(EST.) 국가 순위 | L3: 2025 광종별 가채매장량 | M3: 2025 광종별 가채매장량총계(Rounded) | N3: 2025 광종별 가채매장량 국가 점유율(%) | O3: 2025 광종별 가채매장량 국가순위
D4: Chile | E4: 5510 | F4: 5300 | G4: 23000 | H4: 0.23043478 | I4: 1 | K4: Chile | L4: 180000 | M4: 980000 | N4: 0.18367347 | O4: 1
D5: DRCongo | E5: 2990 | F5: 3200 | G5: 23000 | H5: 0.13913043 | I5: 2 | K5: Australia | L5: 100000 | M5: 980000 | N5: 0.10204082 | O5: 2
D6: Peru | E6: 2740 | F6: 2700 | G6: 23000 | H6: 0.1173913 | I6: 3 | K6: Peru | L6: 85000 | M6: 980000 | N6: 0.086734694 | O6: 3
D7: China | E7: 1840 | F7: 1800 | G7: 23000 | H7: 0.07826087 | I7: 4 | K7: DRCongo | L7: 80000 | M7: 980000 | N7: 0.081632653 | O7: 4
D8: Russia | E8: 1020 | F8: 1300 | G8: 23000 | H8: 0.056521739 | I8: 5 | K8: Russia | L8: 80000 | M8: 980000 | N8: 0.081632653 | O8: 4
D9: United States | E9: 1050 | F9: 1000 | G9: 23000 | H9: 0.043478261 | I9: 6 | K9: Mexico | L9: 53000 | M9: 980000 | N9: 0.054081633 | O9: 6
D10: Zambia | E10: 823 | F10: 940 | G10: 23000 | H10: 0.040869565 | I10: 7 | K10: United States | L10: 47000 | M10: 980000 | N10: 0.047959184 | O10: 7
D11: Australia | E11: 765 | F11: 730 | G11: 23000 | H11: 0.03173913 | I11: 8 | K11: China | L11: 41000 | M11: 980000 | N11: 0.041836735 | O11: 8
D12: Kazakhstan | E12: 724 | F12: 710 | G12: 23000 | H12: 0.030869565 | I12: 9 | K12: Poland | L12: 33000 | M12: 980000 | N12: 0.033673469 | O12: 9
D13: Indonesia | E13: 1010 | F13: 710 | G13: 23000 | H13: 0.030869565 | I13: 9 | K13: Zambia | L13: 21000 | M13: 980000 | N13: 0.021428571 | O13: 10
D14: Mexico | E14: 717 | F14: 690 | G14: 23000 | H14: 0.03 | I14: 11 | K14: Indonesia | L14: 21000 | M14: 980000 | N14: 0.021428571 | O14: 10
D15: Canada | E15: 515 | F15: 500 | G15: 23000 | H15: 0.02173913 | I15: 12 | K15: Kazakhstan | L15: 20000 | M15: 980000 | N15: 0.020408163 | O15: 12
... D19: 총합계 | E19: 22981 | F19: 23013 | G19: 345000 | H19: 1.0005652 | I19: 122 | K19: 총합계 | L19: 980200 | M19: 14700000 | N19: 1.0002041 | O19: 121

Sheet 국가별
D3: 2024 생산 | E3: 2025 생산(EST.) | F3: 2025 생산(EST.) 계(Rounded) | G3: 2025 광종별 생산(EST.) 국가 점유율(%) | H3: 2025 광종별 생산(EST.) 국가 순위 | K3: 2025 광종별 가채매장량 | L3: 2025 광종별 가채매장량총계(Rounded) | M3: 2025 광종별 가채매장량 국가 점유율(%) | N3: 2025 광종별 가채매장량 국가 순위
C4: Garnet | D4: 348000 | E4: 350000 | F4: 730000 | G4: 0.47945205 | H4: 1 | J4: Lead | K4: 34000 | L4: 95000 | M4: 0.35789474 | N4: 1
C5: Titanium(Rutile) | D5: 200 | E5: 200 | F5: 450 | G5: 0.44444444 | H5: 1 | J5: Vanadium | K5: 10000000 | L5: 21000000 | M5: 0.47619048 | N5: 1
C6: Iron | D6: 607000 | E6: 600000 | F6: 1600000 | G6: 0.375 | H6: 1 | J6: Titanium(Ilmentite) | K6: 170000 | L6: 490000 | M6: 0.34693878 | N6: 1
C7: Lithium | D7: 82700 | E7: 92000 | F7: 290000 | G7: 0.31724138 | H7: 1 | J7: Iron | K7: 27000000 | L7: 87000000 | M7: 0.31034483 | N7: 1
C8: Bauxite | D8: 100000 | E8: 97000 | F8: 440000 | G8: 0.22045455 | H8: 2 | J8: Titanium(Rutile) | K8: 35000 | L8: 49000 | M8: 0.71428571 | N8: 1
C9: Lead | D9: 481 | E9: 480 | F9: 4500 | G9: 0.10666667 | H9: 2 | J9: Gold | K9: 13000 | L9: 66000 | M9: 0.1969697 | N9: 1
C10: Gold | D10: 284 | E10: 280 | F10: 3300 | G10: 0.084848485 | H10: 3 | J10: Manganese | K10: 580000 | L10: 1800000 | M10: 0.32222222 | N10: 1
C11: Rare earths | D11: 29000 | E11: 29000 | F11: 390000 | G11: 0.074358974 | H11: 3 | J11: Lithium | K11: 8400000 | L11: 37000000 | M11: 0.22702703 | N11: 2
C12: Manganese | D12: 1600 | E12: 1600 | F12: 20000 | G12: 0.08 | H12: 4 | J12: Nickel | K12: 25000000 | L12: 140000000 | M12: 0.17857143 | N12: 2
C13: Titanium(Ilmentite) | D13: 600 | E13: 780 | F13: 9400 | G13: 0.082978723 | H13: 4 | J13: Cobalt | K13: 1700000 | L13: 12000000 | M13: 0.14166667 | N13: 2
C14: Cobalt | D14: 4780 | E14: 3700 | F14: 310000 | G14: 0.011935484 | H14: 5 | J14: Copper | K14: 100000 | L14: 980000 | M14: 0.10204082 | N14: 2
C15: Tantalum | D15: 52 | E15: 50 | F15: 2500 | G15: 0.02 | H15: 6 | J15: Tantalum | K15: 120000 | L15: 0 | M15: 0 | N15: 2
... C25: Phosphorus | D25: 2500 | E25: 2500 | F25: 250000 | G25: 0.01 | H25: 13 | J25: 총합계 | K25: 86333000 | L25: 525590000 | M25: 4.0878754 | N25: 61
C26: Limestone | D26: 1890 | E26: 1900 | F26: 420000 | G26: 0.0045238095 | H26: 13
C27: Molybdenum | D27: 600 | E27: 1000 | F27: 260000 | G27: 0.0038461538 | H27: 13
C28: Gypsum | D28: 4200 | E28: 4200 | F28: 160000 | G28: 0.02625 | H28: 14
C29: Sulfur | D29: 900 | E29: 900 | F29: 84000 | G29: 0.010714286 | H29: 16
C30: Nitrogen | D30: 1500 | E30: 1500 | F30: 160000 | G30: 0.009375 | H30: 19
C31: 총합계 | D31: 1300650 | E31: 1249167 | F31: 9621750 | G31: 0.094771176 | H31: 195

Sheet 피벗전용데이터
A1: SOURCE | B1: COMMODITY | C1: COUNTRY | D1: TYPE | E1: UNIT | F1: 2024 생산 | G1: 2025 생산(EST.) | H1: 2025 생산(EST.) 계(Rounded) | I1: 2025 광종별 생산(EST.) 국가 점유율(%) | J1: 2025 광종별 생산(EST.) 국가 순위 | K1: 2025 광종별 가채매장량 | L1: 2025 광종별 가채매장량총계(Rounded) | M1: 2025 광종별 가채매장량 국가 점유율(%) | N1: 2025 광종별 가채매장량 국가 순위
A2: =IF(ISNUMBER(SEARCH("World",'RawData'!C2)),"",'RawData'!A2) -> MCS2026 | B2: =IF(ISNUMBER(SEARCH("World",'RawData'!C2)),"",'RawData'!B2) -> Antimony | C2: =IF(ISNUMBER(SEARCH("World",'RawData'!C2)),"",'RawData'!C2) -> Australia | D2: =IF(ISNUMBER(SEARCH("World",'RawData'!C2)),"",'RawData'!D2) -> Mine production, antimony content | E2: =IF(ISNUMBER(SEARCH("World",'RawData'!C2)),"",IF('RawData'!E2="WT001","kg",IF('RawData'!E2="WT002","ton",IF('RawData'!E2="WT003","k ton","")))) -> ton | F2: =IF(ISNUMBER(SEARCH("World",'RawData'!C2)),"",'RawData'!F2) -> 1270 | G2: =IF(ISNUMBER(SEARCH("World",'RawData'!C2)),"",'RawData'!G2) -> 1300 | H2: =IF(ISNUMBER(SEARCH("World",'RawData'!C2)),"",SUMIFS('RawData'!G:G,'RawData'!B:B,'RawData'!B2,'RawData'!C:C,"*World*")) -> 110000 | I2: =IF(ISNUMBER(SEARCH("World",'RawData'!C2)),"",IFERROR(G2/H2,"-")) -> 0.011818182 | J2: =IF(ISNUMBER(SEARCH("World",'RawData'!C2)),"",IF(ISNUMBER(SEARCH("Other",C2)),COUNTIFS('RawData'!B:B,B2,'RawData'!C:C,"<>*World*"),IF(OR(G2="",G2=0),"-",SUMPRODUCT(('RawData'!B$2:B$822=B2)*('RawData'!G$2:G$822>G2)*(ISERROR(SEARCH("World",'RawData'!C$2:C$822)))*(ISERROR(SEARCH("Other",'RawData'!C$2:C$822))))+1))) -> 7 | K2: =IF(ISNUMBER(SEARCH("World",'RawData'!C2)),"",'RawData'!H2) -> 110000 | L2: =IF(ISNUMBER(SEARCH("World",'RawData'!C2)),"",SUMIFS('RawData'!H:H,'RawData'!B:B,'RawData'!B2,'RawData'!C:C,"*World*")) -> 2000000 | M2: =IF(ISNUMBER(SEARCH("World",'RawData'!C2)),"",IFERROR(K2/L2,"-")) -> 0.055 | N2: =IF(ISNUMBER(SEARCH("World",'RawData'!C2)),"",IF(ISNUMBER(SEARCH("Other",C2)),COUNTIFS('RawData'!B:B,B2,'RawData'!C:C,"<>*World*"),IF(OR(K2="",K2=0),"-",SUMPRODUCT(('RawData'!B$2:B$822=B2)*('RawData'!H$2:H$822>K2)*(ISERROR(SEARCH("World",'RawData'!C$2:C$822)))*(ISERROR(SEARCH("Other",'RawData'!C$2:C$822))))+1))) -> 6
A3: =IF(ISNUMBER(SEARCH("World",'RawData'!C3)),"",'RawData'!A3) -> MCS2026 | B3: =IF(ISNUMBER(SEARCH("World",'RawData'!C3)),"",'RawData'!B3) -> Antimony | C3: =IF(ISNUMBER(SEARCH("World",'RawData'!C3)),"",'RawData'!C3) -> Bolivia | D3: =IF(ISNUMBER(SEARCH("World",'RawData'!C3)),"",'RawData'!D3) -> Mine production, antimony content | E3: =IF(ISNUMBER(SEARCH("World",'RawData'!C3)),"",IF('RawData'!E3="WT001","kg",IF('RawData'!E3="WT002","ton",IF('RawData'!E3="WT003","k ton","")))) -> ton | F3: =IF(ISNUMBER(SEARCH("World",'RawData'!C3)),"",'RawData'!F3) -> 5300 | G3: =IF(ISNUMBER(SEARCH("World",'RawData'!C3)),"",'RawData'!G3) -> 5000 | H3: =IF(ISNUMBER(SEARCH("World",'RawData'!C3)),"",SUMIFS('RawData'!G:G,'RawData'!B:B,'RawData'!B3,'RawData'!C:C,"*World*")) -> 110000 | I3: =IF(ISNUMBER(SEARCH("World",'RawData'!C3)),"",IFERROR(G3/H3,"-")) -> 0.045454545 | J3: =IF(ISNUMBER(SEARCH("World",'RawData'!C3)),"",IF(ISNUMBER(SEARCH("Other",C3)),COUNTIFS('RawData'!B:B,B3,'RawData'!C:C,"<>*World*"),IF(OR(G3="",G3=0),"-",SUMPRODUCT(('RawData'!B$2:B$822=B3)*('RawData'!G$2:G$822>G3)*(ISERROR(SEARCH("World",'RawData'!C$2:C$822)))*(ISERROR(SEARCH("Other",'RawData'!C$2:C$822))))+1))) -> 4 | K3: =IF(ISNUMBER(SEARCH("World",'RawData'!C3)),"",'RawData'!H3) -> 310000 | L3: =IF(ISNUMBER(SEARCH("World",'RawData'!C3)),"",SUMIFS('RawData'!H:H,'RawData'!B:B,'RawData'!B3,'RawData'!C:C,"*World*")) -> 2000000 | M3: =IF(ISNUMBER(SEARCH("World",'RawData'!C3)),"",IFERROR(K3/L3,"-")) -> 0.155 | N3: =IF(ISNUMBER(SEARCH("World",'RawData'!C3)),"",IF(ISNUMBER(SEARCH("Other",C3)),COUNTIFS('RawData'!B:B,B3,'RawData'!C:C,"<>*World*"),IF(OR(K3="",K3=0),"-",SUMPRODUCT(('RawData'!B$2:B$822=B3)*('RawData'!H$2:H$822>K3)*(ISERROR(SEARCH("World",'RawData'!C$2:C$822)))*(ISERROR(SEARCH("Other",'RawData'!C$2:C$822))))+1))) -> 3
A4: =IF(ISNUMBER(SEARCH("World",'RawData'!C4)),"",'RawData'!A4) -> MCS2026 | B4: =IF(ISNUMBER(SEARCH("World",'RawData'!C4)),"",'RawData'!B4) -> Antimony | C4: =IF(ISNUMBER(SEARCH("World",'RawData'!C4)),"",'RawData'!C4) -> Canada | D4: =IF(ISNUMBER(SEARCH("World",'RawData'!C4)),"",'RawData'!D4) -> Mine production, antimony content | E4: =IF(ISNUMBER(SEARCH("World",'RawData'!C4)),"",IF('RawData'!E4="WT001","kg",IF('RawData'!E4="WT002","ton",IF('RawData'!E4="WT003","k ton","")))) -> ton | F4: =IF(ISNUMBER(SEARCH("World",'RawData'!C4)),"",'RawData'!F4) -> 0 | G4: =IF(ISNUMBER(SEARCH("World",'RawData'!C4)),"",'RawData'!G4) -> 0 | H4: =IF(ISNUMBER(SEARCH("World",'RawData'!C4)),"",SUMIFS('RawData'!G:G,'RawData'!B:B,'RawData'!B4,'RawData'!C:C,"*World*")) -> 110000 | I4: =IF(ISNUMBER(SEARCH("World",'RawData'!C4)),"",IFERROR(G4/H4,"-")) -> 0 | J4: =IF(ISNUMBER(SEARCH("World",'RawData'!C4)),"",IF(ISNUMBER(SEARCH("Other",C4)),COUNTIFS('RawData'!B:B,B4,'RawData'!C:C,"<>*World*"),IF(OR(G4="",G4=0),"-",SUMPRODUCT(('RawData'!B$2:B$822=B4)*('RawData'!G$2:G$822>G4)*(ISERROR(SEARCH("World",'RawData'!C$2:C$822)))*(ISERROR(SEARCH("Other",'RawData'!C$2:C$822))))+1))) -> - | K4: =IF(ISNUMBER(SEARCH("World",'RawData'!C4)),"",'RawData'!H4) -> 78000 | L4: =IF(ISNUMBER(SEARCH("World",'RawData'!C4)),"",SUMIFS('RawData'!H:H,'RawData'!B:B,'RawData'!B4,'RawData'!C:C,"*World*")) -> 2000000 | M4: =IF(ISNUMBER(SEARCH("World",'RawData'!C4)),"",IFERROR(K4/L4,"-")) -> 0.039 | N4: =IF(ISNUMBER(SEARCH("World",'RawData'!C4)),"",IF(ISNUMBER(SEARCH("Other",C4)),COUNTIFS('RawData'!B:B,B4,'RawData'!C:C,"<>*World*"),IF(OR(K4="",K4=0),"-",SUMPRODUCT(('RawData'!B$2:B$822=B4)*('RawData'!H$2:H$822>K4)*(ISERROR(SEARCH("World",'RawData'!C$2:C$822)))*(ISERROR(SEARCH("Other",'RawData'!C$2:C$822))))+1))) -> 8
A5: =IF(ISNUMBER(SEARCH("World",'RawData'!C5)),"",'RawData'!A5) -> MCS2026 | B5: =IF(ISNUMBER(SEARCH("World",'RawData'!C5)),"",'RawData'!B5) -> Antimony | C5: =IF(ISNUMBER(SEARCH("World",'RawData'!C5)),"",'RawData'!C5) -> China | D5: =IF(ISNUMBER(SEARCH("World",'RawData'!C5)),"",'RawData'!D5) -> Mine production, antimony content | E5: =IF(ISNUMBER(SEARCH("World",'RawData'!C5)),"",IF('RawData'!E5="WT001","kg",IF('RawData'!E5="WT002","ton",IF('RawData'!E5="WT003","k ton","")))) -> ton | F5: =IF(ISNUMBER(SEARCH("World",'RawData'!C5)),"",'RawData'!F5) -> 40000 | G5: =IF(ISNUMBER(SEARCH("World",'RawData'!C5)),"",'RawData'!G5) -> 40000 | H5: =IF(ISNUMBER(SEARCH("World",'RawData'!C5)),"",SUMIFS('RawData'!G:G,'RawData'!B:B,'RawData'!B5,'RawData'!C:C,"*World*")) -> 110000 | I5: =IF(ISNUMBER(SEARCH("World",'RawData'!C5)),"",IFERROR(G5/H5,"-")) -> 0.36363636 | J5: =IF(ISNUMBER(SEARCH("World",'RawData'!C5)),"",IF(ISNUMBER(SEARCH("Other",C5)),COUNTIFS('RawData'!B:B,B5,'RawData'!C:C,"<>*World*"),IF(OR(G5="",G5=0),"-",SUMPRODUCT(('RawData'!B$2:B$822=B5)*('RawData'!G$2:G$822>G5)*(ISERROR(SEARCH("World",'RawData'!C$2:C$822)))*(ISERROR(SEARCH("Other",'RawData'!C$2:C$822))))+1))) -> 1 | K5: =IF(ISNUMBER(SEARCH("World",'RawData'!C5)),"",'RawData'!H5) -> 830000 | L5: =IF(ISNUMBER(SEARCH("World",'RawData'!C5)),"",SUMIFS('RawData'!H:H,'RawData'!B:B,'RawData'!B5,'RawData'!C:C,"*World*")) -> 2000000 | M5: =IF(ISNUMBER(SEARCH("World",'RawData'!C5)),"",IFERROR(K5/L5,"-")) -> 0.415 | N5: =IF(ISNUMBER(SEARCH("World",'RawData'!C5)),"",IF(ISNUMBER(SEARCH("Other",C5)),COUNTIFS('RawData'!B:B,B5,'RawData'!C:C,"<>*World*"),IF(OR(K5="",K5=0),"-",SUMPRODUCT(('RawData'!B$2:B$822=B5)*('RawData'!H$2:H$822>K5)*(ISERROR(SEARCH("World",'RawData'!C$2:C$822)))*(ISERROR(SEARCH("Other",'RawData'!C$2:C$822))))+1))) -> 1
A6: =IF(ISNUMBER(SEARCH("World",'RawData'!C6)),"",'RawData'!A6) -> MCS2026 | B6: =IF(ISNUMBER(SEARCH("World",'RawData'!C6)),"",'RawData'!B6) -> Antimony | C6: =IF(ISNUMBER(SEARCH("World",'RawData'!C6)),"",'RawData'!C6) -> Guatemala | D6: =IF(ISNUMBER(SEARCH("World",'RawData'!C6)),"",'RawData'!D6) -> Mine production, antimony content | E6: =IF(ISNUMBER(SEARCH("World",'RawData'!C6)),"",IF('RawData'!E6="WT001","kg",IF('RawData'!E6="WT002","ton",IF('RawData'!E6="WT003","k ton","")))) -> ton | F6: =IF(ISNUMBER(SEARCH("World",'RawData'!C6)),"",'RawData'!F6) -> 50 | G6: =IF(ISNUMBER(SEARCH("World",'RawData'!C6)),"",'RawData'!G6) -> 50 | H6: =IF(ISNUMBER(SEARCH("World",'RawData'!C6)),"",SUMIFS('RawData'!G:G,'RawData'!B:B,'RawData'!B6,'RawData'!C:C,"*World*")) -> 110000 | I6: =IF(ISNUMBER(SEARCH("World",'RawData'!C6)),"",IFERROR(G6/H6,"-")) -> 0.00045454545 | J6: =IF(ISNUMBER(SEARCH("World",'RawData'!C6)),"",IF(ISNUMBER(SEARCH("Other",C6)),COUNTIFS('RawData'!B:B,B6,'RawData'!C:C,"<>*World*"),IF(OR(G6="",G6=0),"-",SUMPRODUCT(('RawData'!B$2:B$822=B6)*('RawData'!G$2:G$822>G6)*(ISERROR(SEARCH("World",'RawData'!C$2:C$822)))*(ISERROR(SEARCH("Other",'RawData'!C$2:C$822))))+1))) -> 15 | K6: =IF(ISNUMBER(SEARCH("World",'RawData'!C6)),"",'RawData'!H6) -> 0 | L6: =IF(ISNUMBER(SEARCH("World",'RawData'!C6)),"",SUMIFS('RawData'!H:H,'RawData'!B:B,'RawData'!B6,'RawData'!C:C,"*World*")) -> 2000000 | M6: =IF(ISNUMBER(SEARCH("World",'RawData'!C6)),"",IFERROR(K6/L6,"-")) -> 0 | N6: =IF(ISNUMBER(SEARCH("World",'RawData'!C6)),"",IF(ISNUMBER(SEARCH("Other",C6)),COUNTIFS('RawData'!B:B,B6,'RawData'!C:C,"<>*World*"),IF(OR(K6="",K6=0),"-",SUMPRODUCT(('RawData'!B$2:B$822=B6)*('RawData'!H$2:H$822>K6)*(ISERROR(SEARCH("World",'RawData'!C$2:C$822)))*(ISERROR(SEARCH("Other",'RawData'!C$2:C$822))))+1))) -> -
A7: =IF(ISNUMBER(SEARCH("World",'RawData'!C7)),"",'RawData'!A7) -> MCS2026 | B7: =IF(ISNUMBER(SEARCH("World",'RawData'!C7)),"",'RawData'!B7) -> Antimony | C7: =IF(ISNUMBER(SEARCH("World",'RawData'!C7)),"",'RawData'!C7) -> Iran | D7: =IF(ISNUMBER(SEARCH("World",'RawData'!C7)),"",'RawData'!D7) -> Mine production, antimony content | E7: =IF(ISNUMBER(SEARCH("World",'RawData'!C7)),"",IF('RawData'!E7="WT001","kg",IF('RawData'!E7="WT002","ton",IF('RawData'!E7="WT003","k ton","")))) -> ton | F7: =IF(ISNUMBER(SEARCH("World",'RawData'!C7)),"",'RawData'!F7) -> 90 | G7: =IF(ISNUMBER(SEARCH("World",'RawData'!C7)),"",'RawData'!G7) -> 90 | H7: =IF(ISNUMBER(SEARCH("World",'RawData'!C7)),"",SUMIFS('RawData'!G:G,'RawData'!B:B,'RawData'!B7,'RawData'!C:C,"*World*")) -> 110000 | I7: =IF(ISNUMBER(SEARCH("World",'RawData'!C7)),"",IFERROR(G7/H7,"-")) -> 0.00081818182 | J7: =IF(ISNUMBER(SEARCH("World",'RawData'!C7)),"",IF(ISNUMBER(SEARCH("Other",C7)),COUNTIFS('RawData'!B:B,B7,'RawData'!C:C,"<>*World*"),IF(OR(G7="",G7=0),"-",SUMPRODUCT(('RawData'!B$2:B$822=B7)*('RawData'!G$2:G$822>G7)*(ISERROR(SEARCH("World",'RawData'!C$2:C$822)))*(ISERROR(SEARCH("Other",'RawData'!C$2:C$822))))+1))) -> 14 | K7: =IF(ISNUMBER(SEARCH("World",'RawData'!C7)),"",'RawData'!H7) -> 0 | L7: =IF(ISNUMBER(SEARCH("World",'RawData'!C7)),"",SUMIFS('RawData'!H:H,'RawData'!B:B,'RawData'!B7,'RawData'!C:C,"*World*")) -> 2000000 | M7: =IF(ISNUMBER(SEARCH("World",'RawData'!C7)),"",IFERROR(K7/L7,"-")) -> 0 | N7: =IF(ISNUMBER(SEARCH("World",'RawData'!C7)),"",IF(ISNUMBER(SEARCH("Other",C7)),COUNTIFS('RawData'!B:B,B7,'RawData'!C:C,"<>*World*"),IF(OR(K7="",K7=0),"-",SUMPRODUCT(('RawData'!B$2:B$822=B7)*('RawData'!H$2:H$822>K7)*(ISERROR(SEARCH("World",'RawData'!C$2:C$822)))*(ISERROR(SEARCH("Other",'RawData'!C$2:C$822))))+1))) -> -
A8: =IF(ISNUMBER(SEARCH("World",'RawData'!C8)),"",'RawData'!A8) -> MCS2026 | B8: =IF(ISNUMBER(SEARCH("World",'RawData'!C8)),"",'RawData'!B8) -> Antimony | C8: =IF(ISNUMBER(SEARCH("World",'RawData'!C8)),"",'RawData'!C8) -> Kazakhstan | D8: =IF(ISNUMBER(SEARCH("World",'RawData'!C8)),"",'RawData'!D8) -> Mine production, antimony content | E8: =IF(ISNUMBER(SEARCH("World",'RawData'!C8)),"",IF('RawData'!E8="WT001","kg",IF('RawData'!E8="WT002","ton",IF('RawData'!E8="WT003","k ton","")))) -> ton | F8: =IF(ISNUMBER(SEARCH("World",'RawData'!C8)),"",'RawData'!F8) -> 800 | G8: =IF(ISNUMBER(SEARCH("World",'RawData'!C8)),"",'RawData'!G8) -> 800 | H8: =IF(ISNUMBER(SEARCH("World",'RawData'!C8)),"",SUMIFS('RawData'!G:G,'RawData'!B:B,'RawData'!B8,'RawData'!C:C,"*World*")) -> 110000 | I8: =IF(ISNUMBER(SEARCH("World",'RawData'!C8)),"",IFERROR(G8/H8,"-")) -> 0.0072727273 | J8: =IF(ISNUMBER(SEARCH("World",'RawData'!C8)),"",IF(ISNUMBER(SEARCH("Other",C8)),COUNTIFS('RawData'!B:B,B8,'RawData'!C:C,"<>*World*"),IF(OR(G8="",G8=0),"-",SUMPRODUCT(('RawData'!B$2:B$822=B8)*('RawData'!G$2:G$822>G8)*(ISERROR(SEARCH("World",'RawData'!C$2:C$822)))*(ISERROR(SEARCH("Other",'RawData'!C$2:C$822))))+1))) -> 8 | K8: =IF(ISNUMBER(SEARCH("World",'RawData'!C8)),"",'RawData'!H8) -> 0 | L8: =IF(ISNUMBER(SEARCH("World",'RawData'!C8)),"",SUMIFS('RawData'!H:H,'RawData'!B:B,'RawData'!B8,'RawData'!C:C,"*World*")) -> 2000000 | M8: =IF(ISNUMBER(SEARCH("World",'RawData'!C8)),"",IFERROR(K8/L8,"-")) -> 0 | N8: =IF(ISNUMBER(SEARCH("World",'RawData'!C8)),"",IF(ISNUMBER(SEARCH("Other",C8)),COUNTIFS('RawData'!B:B,B8,'RawData'!C:C,"<>*World*"),IF(OR(K8="",K8=0),"-",SUMPRODUCT(('RawData'!B$2:B$822=B8)*('RawData'!H$2:H$822>K8)*(ISERROR(SEARCH("World",'RawData'!C$2:C$822)))*(ISERROR(SEARCH("Other",'RawData'!C$2:C$822))))+1))) -> -
A9: =IF(ISNUMBER(SEARCH("World",'RawData'!C9)),"",'RawData'!A9) -> MCS2026 | B9: =IF(ISNUMBER(SEARCH("World",'RawData'!C9)),"",'RawData'!B9) -> Antimony | C9: =IF(ISNUMBER(SEARCH("World",'RawData'!C9)),"",'RawData'!C9) -> Kyrgyzstan | D9: =IF(ISNUMBER(SEARCH("World",'RawData'!C9)),"",'RawData'!D9) -> Mine production, antimony content | E9: =IF(ISNUMBER(SEARCH("World",'RawData'!C9)),"",IF('RawData'!E9="WT001","kg",IF('RawData'!E9="WT002","ton",IF('RawData'!E9="WT003","k ton","")))) -> ton | F9: =IF(ISNUMBER(SEARCH("World",'RawData'!C9)),"",'RawData'!F9) -> 700 | G9: =IF(ISNUMBER(SEARCH("World",'RawData'!C9)),"",'RawData'!G9) -> 700 | H9: =IF(ISNUMBER(SEARCH("World",'RawData'!C9)),"",SUMIFS('RawData'!G:G,'RawData'!B:B,'RawData'!B9,'RawData'!C:C,"*World*")) -> 110000 | I9: =IF(ISNUMBER(SEARCH("World",'RawData'!C9)),"",IFERROR(G9/H9,"-")) -> 0.0063636364 | J9: =IF(ISNUMBER(SEARCH("World",'RawData'!C9)),"",IF(ISNUMBER(SEARCH("Other",C9)),COUNTIFS('RawData'!B:B,B9,'RawData'!C:C,"<>*World*"),IF(OR(G9="",G9=0),"-",SUMPRODUCT(('RawData'!B$2:B$822=B9)*('RawData'!G$2:G$822>G9)*(ISERROR(SEARCH("World",'RawData'!C$2:C$822)))*(ISERROR(SEARCH("Other",'RawData'!C$2:C$822))))+1))) -> 9 | K9: =IF(ISNUMBER(SEARCH("World",'RawData'!C9)),"",'RawData'!H9) -> 260000 | L9: =IF(ISNUMBER(SEARCH("World",'RawData'!C9)),"",SUMIFS('RawData'!H:H,'RawData'!B:B,'RawData'!B9,'RawData'!C:C,"*World*")) -> 2000000 | M9: =IF(ISNUMBER(SEARCH("World",'RawData'!C9)),"",IFERROR(K9/L9,"-")) -> 0.13 | N9: =IF(ISNUMBER(SEARCH("World",'RawData'!C9)),"",IF(ISNUMBER(SEARCH("Other",C9)),COUNTIFS('RawData'!B:B,B9,'RawData'!C:C,"<>*World*"),IF(OR(K9="",K9=0),"-",SUMPRODUCT(('RawData'!B$2:B$822=B9)*('RawData'!H$2:H$822>K9)*(ISERROR(SEARCH("World",'RawData'!C$2:C$822)))*(ISERROR(SEARCH("Other",'RawData'!C$2:C$822))))+1))) -> 4
A10: =IF(ISNUMBER(SEARCH("World",'RawData'!C10)),"",'RawData'!A10) -> MCS2026 | B10: =IF(ISNUMBER(SEARCH("World",'RawData'!C10)),"",'RawData'!B10) -> Antimony | C10: =IF(ISNUMBER(SEARCH("World",'RawData'!C10)),"",'RawData'!C10) -> Laos | D10: =IF(ISNUMBER(SEARCH("World",'RawData'!C10)),"",'RawData'!D10) -> Mine production, antimony content | E10: =IF(ISNUMBER(SEARCH("World",'RawData'!C10)),"",IF('RawData'!E10="WT001","kg",IF('RawData'!E10="WT002","ton",IF('RawData'!E10="WT003","k ton","")))) -> ton | F10: =IF(ISNUMBER(SEARCH("World",'RawData'!C10)),"",'RawData'!F10) -> 200 | G10: =IF(ISNUMBER(SEARCH("World",'RawData'!C10)),"",'RawData'!G10) -> 200 | H10: =IF(ISNUMBER(SEARCH("World",'RawData'!C10)),"",SUMIFS('RawData'!G:G,'RawData'!B:B,'RawData'!B10,'RawData'!C:C,"*World*")) -> 110000 | I10: =IF(ISNUMBER(SEARCH("World",'RawData'!C10)),"",IFERROR(G10/H10,"-")) -> 0.0018181818 | J10: =IF(ISNUMBER(SEARCH("World",'RawData'!C10)),"",IF(ISNUMBER(SEARCH("Other",C10)),COUNTIFS('RawData'!B:B,B10,'RawData'!C:C,"<>*World*"),IF(OR(G10="",G10=0),"-",SUMPRODUCT(('RawData'!B$2:B$822=B10)*('RawData'!G$2:G$822>G10)*(ISERROR(SEARCH("World",'RawData'!C$2:C$822)))*(ISERROR(SEARCH("Other",'RawData'!C$2:C$822))))+1))) -> 13 | K10: =IF(ISNUMBER(SEARCH("World",'RawData'!C10)),"",'RawData'!H10) -> 0 | L10: =IF(ISNUMBER(SEARCH("World",'RawData'!C10)),"",SUMIFS('RawData'!H:H,'RawData'!B:B,'RawData'!B10,'RawData'!C:C,"*World*")) -> 2000000 | M10: =IF(ISNUMBER(SEARCH("World",'RawData'!C10)),"",IFERROR(K10/L10,"-")) -> 0 | N10: =IF(ISNUMBER(SEARCH("World",'RawData'!C10)),"",IF(ISNUMBER(SEARCH("Other",C10)),COUNTIFS('RawData'!B:B,B10,'RawData'!C:C,"<>*World*"),IF(OR(K10="",K10=0),"-",SUMPRODUCT(('RawData'!B$2:B$822=B10)*('RawData'!H$2:H$822>K10)*(ISERROR(SEARCH("World",'RawData'!C$2:C$822)))*(ISERROR(SEARCH("Other",'RawData'!C$2:C$822))))+1))) -> -
A11: =IF(ISNUMBER(SEARCH("World",'RawData'!C11)),"",'RawData'!A11) -> MCS2026 | B11: =IF(ISNUMBER(SEARCH("World",'RawData'!C11)),"",'RawData'!B11) -> Antimony | C11: =IF(ISNUMBER(SEARCH("World",'RawData'!C11)),"",'RawData'!C11) -> Mexico | D11: =IF(ISNUMBER(SEARCH("World",'RawData'!C11)),"",'RawData'!D11) -> Mine production, antimony content | E11: =IF(ISNUMBER(SEARCH("World",'RawData'!C11)),"",IF('RawData'!E11="WT001","kg",IF('RawData'!E11="WT002","ton",IF('RawData'!E11="WT003","k ton","")))) -> ton | F11: =IF(ISNUMBER(SEARCH("World",'RawData'!C11)),"",'RawData'!F11) -> 600 | G11: =IF(ISNUMBER(SEARCH("World",'RawData'!C11)),"",'RawData'!G11) -> 600 | H11: =IF(ISNUMBER(SEARCH("World",'RawData'!C11)),"",SUMIFS('RawData'!G:G,'RawData'!B:B,'RawData'!B11,'RawData'!C:C,"*World*")) -> 110000 | I11: =IF(ISNUMBER(SEARCH("World",'RawData'!C11)),"",IFERROR(G11/H11,"-")) -> 0.0054545455 | J11: =IF(ISNUMBER(SEARCH("World",'RawData'!C11)),"",IF(ISNUMBER(SEARCH("Other",C11)),COUNTIFS('RawData'!B:B,B11,'RawData'!C:C,"<>*World*"),IF(OR(G11="",G11=0),"-",SUMPRODUCT(('RawData'!B$2:B$822=B11)*('RawData'!G$2:G$822>G11)*(ISERROR(SEARCH("World",'RawData'!C$2:C$822)))*(ISERROR(SEARCH("Other",'RawData'!C$2:C$822))))+1))) -> 10 | K11: =IF(ISNUMBER(SEARCH("World",'RawData'!C11)),"",'RawData'!H11) -> 18000 | L11: =IF(ISNUMBER(SEARCH("World",'RawData'!C11)),"",SUMIFS('RawData'!H:H,'RawData'!B:B,'RawData'!B11,'RawData'!C:C,"*World*")) -> 2000000 | M11: =IF(ISNUMBER(SEARCH("World",'RawData'!C11)),"",IFERROR(K11/L11,"-")) -> 0.009 | N11: =IF(ISNUMBER(SEARCH("World",'RawData'!C11)),"",IF(ISNUMBER(SEARCH("Other",C11)),COUNTIFS('RawData'!B:B,B11,'RawData'!C:C,"<>*World*"),IF(OR(K11="",K11=0),"-",SUMPRODUCT(('RawData'!B$2:B$822=B11)*('RawData'!H$2:H$822>K11)*(ISERROR(SEARCH("World",'RawData'!C$2:C$822)))*(ISERROR(SEARCH("Other",'RawData'!C$2:C$822))))+1))) -> 13
A12: =IF(ISNUMBER(SEARCH("World",'RawData'!C12)),"",'RawData'!A12) -> MCS2026 | B12: =IF(ISNUMBER(SEARCH("World",'RawData'!C12)),"",'RawData'!B12) -> Antimony | C12: =IF(ISNUMBER(SEARCH("World",'RawData'!C12)),"",'RawData'!C12) -> Myanmar | D12: =IF(ISNUMBER(SEARCH("World",'RawData'!C12)),"",'RawData'!D12) -> Mine production, antimony content | E12: =IF(ISNUMBER(SEARCH("World",'RawData'!C12)),"",IF('RawData'!E12="WT001","kg",IF('RawData'!E12="WT002","ton",IF('RawData'!E12="WT003","k ton","")))) -> ton | F12: =IF(ISNUMBER(SEARCH("World",'RawData'!C12)),"",'RawData'!F12) -> 4500 | G12: =IF(ISNUMBER(SEARCH("World",'RawData'!C12)),"",'RawData'!G12) -> 4500 | H12: =IF(ISNUMBER(SEARCH("World",'RawData'!C12)),"",SUMIFS('RawData'!G:G,'RawData'!B:B,'RawData'!B12,'RawData'!C:C,"*World*")) -> 110000 | I12: =IF(ISNUMBER(SEARCH("World",'RawData'!C12)),"",IFERROR(G12/H12,"-")) -> 0.040909091 | J12: =IF(ISNUMBER(SEARCH("World",'RawData'!C12)),"",IF(ISNUMBER(SEARCH("Other",C12)),COUNTIFS('RawData'!B:B,B12,'RawData'!C:C,"<>*World*"),IF(OR(G12="",G12=0),"-",SUMPRODUCT(('RawData'!B$2:B$822=B12)*('RawData'!G$2:G$822>G12)*(ISERROR(SEARCH("World",'RawData'!C$2:C$822)))*(ISERROR(SEARCH("Other",'RawData'!C$2:C$822))))+1))) -> 5 | K12: =IF(ISNUMBER(SEARCH("World",'RawData'!C12)),"",'RawData'!H12) -> 140000 | L12: =IF(ISNUMBER(SEARCH("World",'RawData'!C12)),"",SUMIFS('RawData'!H:H,'RawData'!B:B,'RawData'!B12,'RawData'!C:C,"*World*")) -> 2000000 | M12: =IF(ISNUMBER(SEARCH("World",'RawData'!C12)),"",IFERROR(K12/L12,"-")) -> 0.07 | N12: =IF(ISNUMBER(SEARCH("World",'RawData'!C12)),"",IF(ISNUMBER(SEARCH("Other",C12)),COUNTIFS('RawData'!B:B,B12,'RawData'!C:C,"<>*World*"),IF(OR(K12="",K12=0),"-",SUMPRODUCT(('RawData'!B$2:B$822=B12)*('RawData'!H$2:H$822>K12)*(ISERROR(SEARCH("World",'RawData'!C$2:C$822)))*(ISERROR(SEARCH("Other",'RawData'!C$2:C$822))))+1))) -> 5
A13: =IF(ISNUMBER(SEARCH("World",'RawData'!C13)),"",'RawData'!A13) -> MCS2026 | B13: =IF(ISNUMBER(SEARCH("World",'RawData'!C13)),"",'RawData'!B13) -> Antimony | C13: =IF(ISNUMBER(SEARCH("World",'RawData'!C13)),"",'RawData'!C13) -> Pakistan | D13: =IF(ISNUMBER(SEARCH("World",'RawData'!C13)),"",'RawData'!D13) -> Mine production, antimony content | E13: =IF(ISNUMBER(SEARCH("World",'RawData'!C13)),"",IF('RawData'!E13="WT001","kg",IF('RawData'!E13="WT002","ton",IF('RawData'!E13="WT003","k ton","")))) -> ton | F13: =IF(ISNUMBER(SEARCH("World",'RawData'!C13)),"",'RawData'!F13) -> 260 | G13: =IF(ISNUMBER(SEARCH("World",'RawData'!C13)),"",'RawData'!G13) -> 260 | H13: =IF(ISNUMBER(SEARCH("World",'RawData'!C13)),"",SUMIFS('RawData'!G:G,'RawData'!B:B,'RawData'!B13,'RawData'!C:C,"*World*")) -> 110000 | I13: =IF(ISNUMBER(SEARCH("World",'RawData'!C13)),"",IFERROR(G13/H13,"-")) -> 0.0023636364 | J13: =IF(ISNUMBER(SEARCH("World",'RawData'!C13)),"",IF(ISNUMBER(SEARCH("Other",C13)),COUNTIFS('RawData'!B:B,B13,'RawData'!C:C,"<>*World*"),IF(OR(G13="",G13=0),"-",SUMPRODUCT(('RawData'!B$2:B$822=B13)*('RawData'!G$2:G$822>G13)*(ISERROR(SEARCH("World",'RawData'!C$2:C$822)))*(ISERROR(SEARCH("Other",'RawData'!C$2:C$822))))+1))) -> 11 | K13: =IF(ISNUMBER(SEARCH("World",'RawData'!C13)),"",'RawData'!H13) -> 26000 | L13: =IF(ISNUMBER(SEARCH("World",'RawData'!C13)),"",SUMIFS('RawData'!H:H,'RawData'!B:B,'RawData'!B13,'RawData'!C:C,"*World*")) -> 2000000 | M13: =IF(ISNUMBER(SEARCH("World",'RawData'!C13)),"",IFERROR(K13/L13,"-")) -> 0.013 | N13: =IF(ISNUMBER(SEARCH("World",'RawData'!C13)),"",IF(ISNUMBER(SEARCH("Other",C13)),COUNTIFS('RawData'!B:B,B13,'RawData'!C:C,"<>*World*"),IF(OR(K13="",K13=0),"-",SUMPRODUCT(('RawData'!B$2:B$822=B13)*('RawData'!H$2:H$822>K13)*(ISERROR(SEARCH("World",'RawData'!C$2:C$822)))*(ISERROR(SEARCH("Other",'RawData'!C$2:C$822))))+1))) -> 12
... A18: =IF(ISNUMBER(SEARCH("World",'RawData'!C18)),"",'RawData'!A18) -> MCS2026 | B18: =IF(ISNUMBER(SEARCH("World",'RawData'!C18)),"",'RawData'!B18) -> Antimony | C18: =IF(ISNUMBER(SEARCH("World",'RawData'!C18)),"",'RawData'!C18) -> Vietnam | D18: =IF(ISNUMBER(SEARCH("World",'RawData'!C18)),"",'RawData'!D18) -> Mine production, antimony content | E18: =IF(ISNUMBER(SEARCH("World",'RawData'!C18)),"",IF('RawData'!E18="WT001","kg",IF('RawData'!E18="WT002","ton",IF('RawData'!E18="WT003","k ton","")))) -> ton | F18: =IF(ISNUMBER(SEARCH("World",'RawData'!C18)),"",'RawData'!F18) -> 220 | G18: =IF(ISNUMBER(SEARCH("World",'RawData'!C18)),"",'RawData'!G18) -> 220 | H18: =IF(ISNUMBER(SEARCH("World",'RawData'!C18)),"",SUMIFS('RawData'!G:G,'RawData'!B:B,'RawData'!B18,'RawData'!C:C,"*World*")) -> 110000 | I18: =IF(ISNUMBER(SEARCH("World",'RawData'!C18)),"",IFERROR(G18/H18,"-")) -> 0.002 | J18: =IF(ISNUMBER(SEARCH("World",'RawData'!C18)),"",IF(ISNUMBER(SEARCH("Other",C18)),COUNTIFS('RawData'!B:B,B18,'RawData'!C:C,"<>*World*"),IF(OR(G18="",G18=0),"-",SUMPRODUCT(('RawData'!B$2:B$822=B18)*('RawData'!G$2:G$822>G18)*(ISERROR(SEARCH("World",'RawData'!C$2:C$822)))*(ISERROR(SEARCH("Other",'RawData'!C$2:C$822))))+1))) -> 12 | K18: =IF(ISNUMBER(SEARCH("World",'RawData'!C18)),"",'RawData'!H18) -> 54000 | L18: =IF(ISNUMBER(SEARCH("World",'RawData'!C18)),"",SUMIFS('RawData'!H:H,'RawData'!B:B,'RawData'!B18,'RawData'!C:C,"*World*")) -> 2000000 | M18: =IF(ISNUMBER(SEARCH("World",'RawData'!C18)),"",IFERROR(K18/L18,"-")) -> 0.027 | N18: =IF(ISNUMBER(SEARCH("World",'RawData'!C18)),"",IF(ISNUMBER(SEARCH("Other",C18)),COUNTIFS('RawData'!B:B,B18,'RawData'!C:C,"<>*World*"),IF(OR(K18="",K18=0),"-",SUMPRODUCT(('RawData'!B$2:B$822=B18)*('RawData'!H$2:H$822>K18)*(ISERROR(SEARCH("World",'RawData'!C$2:C$822)))*(ISERROR(SEARCH("Other",'RawData'!C$2:C$822))))+1))) -> 11
A19: =IF(ISNUMBER(SEARCH("World",'RawData'!C20)),"",'RawData'!A20) -> MCS2026 | B19: =IF(ISNUMBER(SEARCH("World",'RawData'!C20)),"",'RawData'!B20) -> Arsenic | C19: =IF(ISNUMBER(SEARCH("World",'RawData'!C20)),"",'RawData'!C20) -> Belgium | D19: =IF(ISNUMBER(SEARCH("World",'RawData'!C20)),"",'RawData'!D20) -> Plant production, arsenic trioxide or calculated equivalent. | E19: =IF(ISNUMBER(SEARCH("World",'RawData'!C20)),"",IF('RawData'!E20="WT001","kg",IF('RawData'!E20="WT002","ton",IF('RawData'!E20="WT003","k ton","")))) -> ton | F19: =IF(ISNUMBER(SEARCH("World",'RawData'!C20)),"",'RawData'!F20) -> 1000 | G19: =IF(ISNUMBER(SEARCH("World",'RawData'!C20)),"",'RawData'!G20) -> 1000 | H19: =IF(ISNUMBER(SEARCH("World",'RawData'!C20)),"",SUMIFS('RawData'!G:G,'RawData'!B:B,'RawData'!B20,'RawData'!C:C,"*World*")) -> 61000 | I19: =IF(ISNUMBER(SEARCH("World",'RawData'!C20)),"",IFERROR(G19/H19,"-")) -> 0.016393443 | J19: =IF(ISNUMBER(SEARCH("World",'RawData'!C20)),"",IF(ISNUMBER(SEARCH("Other",C19)),COUNTIFS('RawData'!B:B,B19,'RawData'!C:C,"<>*World*"),IF(OR(G19="",G19=0),"-",SUMPRODUCT(('RawData'!B$2:B$822=B19)*('RawData'!G$2:G$822>G19)*(ISERROR(SEARCH("World",'RawData'!C$2:C$822)))*(ISERROR(SEARCH("Other",'RawData'!C$2:C$822))))+1))) -> 4 | K19: =IF(ISNUMBER(SEARCH("World",'RawData'!C20)),"",'RawData'!H20) -> 0 | L19: =IF(ISNUMBER(SEARCH("World",'RawData'!C20)),"",SUMIFS('RawData'!H:H,'RawData'!B:B,'RawData'!B20,'RawData'!C:C,"*World*")) -> 0 | M19: =IF(ISNUMBER(SEARCH("World",'RawData'!C20)),"",IFERROR(K19/L19,"-")) -> - | N19: =IF(ISNUMBER(SEARCH("World",'RawData'!C20)),"",IF(ISNUMBER(SEARCH("Other",C19)),COUNTIFS('RawData'!B:B,B19,'RawData'!C:C,"<>*World*"),IF(OR(K19="",K19=0),"-",SUMPRODUCT(('RawData'!B$2:B$822=B19)*('RawData'!H$2:H$822>K19)*(ISERROR(SEARCH("World",'RawData'!C$2:C$822)))*(ISERROR(SEARCH("Other",'RawData'!C$2:C$822))))+1))) -> -
A20: =IF(ISNUMBER(SEARCH("World",'RawData'!C21)),"",'RawData'!A21) -> MCS2026 | B20: =IF(ISNUMBER(SEARCH("World",'RawData'!C21)),"",'RawData'!B21) -> Arsenic | C20: =IF(ISNUMBER(SEARCH("World",'RawData'!C21)),"",'RawData'!C21) -> China | D20: =IF(ISNUMBER(SEARCH("World",'RawData'!C21)),"",'RawData'!D21) -> Plant production, arsenic trioxide or calculated equivalent. | E20: =IF(ISNUMBER(SEARCH("World",'RawData'!C21)),"",IF('RawData'!E21="WT001","kg",IF('RawData'!E21="WT002","ton",IF('RawData'!E21="WT003","k ton","")))) -> ton | F20: =IF(ISNUMBER(SEARCH("World",'RawData'!C21)),"",'RawData'!F21) -> 24000 | G20: =IF(ISNUMBER(SEARCH("World",'RawData'!C21)),"",'RawData'!G21) -> 24000 | H20: =IF(ISNUMBER(SEARCH("World",'RawData'!C21)),"",SUMIFS('RawData'!G:G,'RawData'!B:B,'RawData'!B21,'RawData'!C:C,"*World*")) -> 61000 | I20: =IF(ISNUMBER(SEARCH("World",'RawData'!C21)),"",IFERROR(G20/H20,"-")) -> 0.39344262 | J20: =IF(ISNUMBER(SEARCH("World",'RawData'!C21)),"",IF(ISNUMBER(SEARCH("Other",C20)),COUNTIFS('RawData'!B:B,B20,'RawData'!C:C,"<>*World*"),IF(OR(G20="",G20=0),"-",SUMPRODUCT(('RawData'!B$2:B$822=B20)*('RawData'!G$2:G$822>G20)*(ISERROR(SEARCH("World",'RawData'!C$2:C$822)))*(ISERROR(SEARCH("Other",'RawData'!C$2:C$822))))+1))) -> 2 | K20: =IF(ISNUMBER(SEARCH("World",'RawData'!C21)),"",'RawData'!H21) -> 0 | L20: =IF(ISNUMBER(SEARCH("World",'RawData'!C21)),"",SUMIFS('RawData'!H:H,'RawData'!B:B,'RawData'!B21,'RawData'!C:C,"*World*")) -> 0 | M20: =IF(ISNUMBER(SEARCH("World",'RawData'!C21)),"",IFERROR(K20/L20,"-")) -> - | N20: =IF(ISNUMBER(SEARCH("World",'RawData'!C21)),"",IF(ISNUMBER(SEARCH("Other",C20)),COUNTIFS('RawData'!B:B,B20,'RawData'!C:C,"<>*World*"),IF(OR(K20="",K20=0),"-",SUMPRODUCT(('RawData'!B$2:B$822=B20)*('RawData'!H$2:H$822>K20)*(ISERROR(SEARCH("World",'RawData'!C$2:C$822)))*(ISERROR(SEARCH("Other",'RawData'!C$2:C$822))))+1))) -> -
A21: =IF(ISNUMBER(SEARCH("World",'RawData'!C22)),"",'RawData'!A22) -> MCS2026 | B21: =IF(ISNUMBER(SEARCH("World",'RawData'!C22)),"",'RawData'!B22) -> Arsenic | C21: =IF(ISNUMBER(SEARCH("World",'RawData'!C22)),"",'RawData'!C22) -> Japan | D21: =IF(ISNUMBER(SEARCH("World",'RawData'!C22)),"",'RawData'!D22) -> Plant production, arsenic trioxide or calculated equivalent. | E21: =IF(ISNUMBER(SEARCH("World",'RawData'!C22)),"",IF('RawData'!E22="WT001","kg",IF('RawData'!E22="WT002","ton",IF('RawData'!E22="WT003","k ton","")))) -> ton | F21: =IF(ISNUMBER(SEARCH("World",'RawData'!C22)),"",'RawData'!F22) -> 40 | G21: =IF(ISNUMBER(SEARCH("World",'RawData'!C22)),"",'RawData'!G22) -> 0 | H21: =IF(ISNUMBER(SEARCH("World",'RawData'!C22)),"",SUMIFS('RawData'!G:G,'RawData'!B:B,'RawData'!B22,'RawData'!C:C,"*World*")) -> 61000 | I21: =IF(ISNUMBER(SEARCH("World",'RawData'!C22)),"",IFERROR(G21/H21,"-")) -> 0 | J21: =IF(ISNUMBER(SEARCH("World",'RawData'!C22)),"",IF(ISNUMBER(SEARCH("Other",C21)),COUNTIFS('RawData'!B:B,B21,'RawData'!C:C,"<>*World*"),IF(OR(G21="",G21=0),"-",SUMPRODUCT(('RawData'!B$2:B$822=B21)*('RawData'!G$2:G$822>G21)*(ISERROR(SEARCH("World",'RawData'!C$2:C$822)))*(ISERROR(SEARCH("Other",'RawData'!C$2:C$822))))+1))) -> - | K21: =IF(ISNUMBER(SEARCH("World",'RawData'!C22)),"",'RawData'!H22) -> 0 | L21: =IF(ISNUMBER(SEARCH("World",'RawData'!C22)),"",SUMIFS('RawData'!H:H,'RawData'!B:B,'RawData'!B22,'RawData'!C:C,"*World*")) -> 0 | M21: =IF(ISNUMBER(SEARCH("World",'RawData'!C22)),"",IFERROR(K21/L21,"-")) -> - | N21: =IF(ISNUMBER(SEARCH("World",'RawData'!C22)),"",IF(ISNUMBER(SEARCH("Other",C21)),COUNTIFS('RawData'!B:B,B21,'RawData'!C:C,"<>*World*"),IF(OR(K21="",K21=0),"-",SUMPRODUCT(('RawData'!B$2:B$822=B21)*('RawData'!H$2:H$822>K21)*(ISERROR(SEARCH("World",'RawData'!C$2:C$822)))*(ISERROR(SEARCH("Other",'RawData'!C$2:C$822))))+1))) -> -
A22: =IF(ISNUMBER(SEARCH("World",'RawData'!C23)),"",'RawData'!A23) -> MCS2026 | B22: =IF(ISNUMBER(SEARCH("World",'RawData'!C23)),"",'RawData'!B23) -> Arsenic | C22: =IF(ISNUMBER(SEARCH("World",'RawData'!C23)),"",'RawData'!C23) -> Morocco | D22: =IF(ISNUMBER(SEARCH("World",'RawData'!C23)),"",'RawData'!D23) -> Plant production, arsenic trioxide or calculated equivalent. | E22: =IF(ISNUMBER(SEARCH("World",'RawData'!C23)),"",IF('RawData'!E23="WT001","kg",IF('RawData'!E23="WT002","ton",IF('RawData'!E23="WT003","k ton","")))) -> ton | F22: =IF(ISNUMBER(SEARCH("World",'RawData'!C23)),"",'RawData'!F23) -> 6000 | G22: =IF(ISNUMBER(SEARCH("World",'RawData'!C23)),"",'RawData'!G23) -> 5000 | H22: =IF(ISNUMBER(SEARCH("World",'RawData'!C23)),"",SUMIFS('RawData'!G:G,'RawData'!B:B,'RawData'!B23,'RawData'!C:C,"*World*")) -> 61000 | I22: =IF(ISNUMBER(SEARCH("World",'RawData'!C23)),"",IFERROR(G22/H22,"-")) -> 0.081967213 | J22: =IF(ISNUMBER(SEARCH("World",'RawData'!C23)),"",IF(ISNUMBER(SEARCH("Other",C22)),COUNTIFS('RawData'!B:B,B22,'RawData'!C:C,"<>*World*"),IF(OR(G22="",G22=0),"-",SUMPRODUCT(('RawData'!B$2:B$822=B22)*('RawData'!G$2:G$822>G22)*(ISERROR(SEARCH("World",'RawData'!C$2:C$822)))*(ISERROR(SEARCH("Other",'RawData'!C$2:C$822))))+1))) -> 3 | K22: =IF(ISNUMBER(SEARCH("World",'RawData'!C23)),"",'RawData'!H23) -> 0 | L22: =IF(ISNUMBER(SEARCH("World",'RawData'!C23)),"",SUMIFS('RawData'!H:H,'RawData'!B:B,'RawData'!B23,'RawData'!C:C,"*World*")) -> 0 | M22: =IF(ISNUMBER(SEARCH("World",'RawData'!C23)),"",IFERROR(K22/L22,"-")) -> - | N22: =IF(ISNUMBER(SEARCH("World",'RawData'!C23)),"",IF(ISNUMBER(SEARCH("Other",C22)),COUNTIFS('RawData'!B:B,B22,'RawData'!C:C,"<>*World*"),IF(OR(K22="",K22=0),"-",SUMPRODUCT(('RawData'!B$2:B$822=B22)*('RawData'!H$2:H$822>K22)*(ISERROR(SEARCH("World",'RawData'!C$2:C$822)))*(ISERROR(SEARCH("Other",'RawData'!C$2:C$822))))+1))) -> -
A23: =IF(ISNUMBER(SEARCH("World",'RawData'!C24)),"",'RawData'!A24) -> MCS2026 | B23: =IF(ISNUMBER(SEARCH("World",'RawData'!C24)),"",'RawData'!B24) -> Arsenic | C23: =IF(ISNUMBER(SEARCH("World",'RawData'!C24)),"",'RawData'!C24) -> Peru | D23: =IF(ISNUMBER(SEARCH("World",'RawData'!C24)),"",'RawData'!D24) -> Plant production, arsenic trioxide or calculated equivalent. | E23: =IF(ISNUMBER(SEARCH("World",'RawData'!C24)),"",IF('RawData'!E24="WT001","kg",IF('RawData'!E24="WT002","ton",IF('RawData'!E24="WT003","k ton","")))) -> ton | F23: =IF(ISNUMBER(SEARCH("World",'RawData'!C24)),"",'RawData'!F24) -> 31000 | G23: =IF(ISNUMBER(SEARCH("World",'RawData'!C24)),"",'RawData'!G24) -> 30000 | H23: =IF(ISNUMBER(SEARCH("World",'RawData'!C24)),"",SUMIFS('RawData'!G:G,'RawData'!B:B,'RawData'!B24,'RawData'!C:C,"*World*")) -> 61000 | I23: =IF(ISNUMBER(SEARCH("World",'RawData'!C24)),"",IFERROR(G23/H23,"-")) -> 0.49180328 | J23: =IF(ISNUMBER(SEARCH("World",'RawData'!C24)),"",IF(ISNUMBER(SEARCH("Other",C23)),COUNTIFS('RawData'!B:B,B23,'RawData'!C:C,"<>*World*"),IF(OR(G23="",G23=0),"-",SUMPRODUCT(('RawData'!B$2:B$822=B23)*('RawData'!G$2:G$822>G23)*(ISERROR(SEARCH("World",'RawData'!C$2:C$822)))*(ISERROR(SEARCH("Other",'RawData'!C$2:C$822))))+1))) -> 1 | K23: =IF(ISNUMBER(SEARCH("World",'RawData'!C24)),"",'RawData'!H24) -> 0 | L23: =IF(ISNUMBER(SEARCH("World",'RawData'!C24)),"",SUMIFS('RawData'!H:H,'RawData'!B:B,'RawData'!B24,'RawData'!C:C,"*World*")) -> 0 | M23: =IF(ISNUMBER(SEARCH("World",'RawData'!C24)),"",IFERROR(K23/L23,"-")) -> - | N23: =IF(ISNUMBER(SEARCH("World",'RawData'!C24)),"",IF(ISNUMBER(SEARCH("Other",C23)),COUNTIFS('RawData'!B:B,B23,'RawData'!C:C,"<>*World*"),IF(OR(K23="",K23=0),"-",SUMPRODUCT(('RawData'!B$2:B$822=B23)*('RawData'!H$2:H$822>K23)*(ISERROR(SEARCH("World",'RawData'!C$2:C$822)))*(ISERROR(SEARCH("Other",'RawData'!C$2:C$822))))+1))) -> -
A24: =IF(ISNUMBER(SEARCH("World",'RawData'!C25)),"",'RawData'!A25) -> MCS2026 | B24: =IF(ISNUMBER(SEARCH("World",'RawData'!C25)),"",'RawData'!B25) -> Arsenic | C24: =IF(ISNUMBER(SEARCH("World",'RawData'!C25)),"",'RawData'!C25) -> Russia | D24: =IF(ISNUMBER(SEARCH("World",'RawData'!C25)),"",'RawData'!D25) -> Plant production, arsenic trioxide or calculated equivalent. | E24: =IF(ISNUMBER(SEARCH("World",'RawData'!C25)),"",IF('RawData'!E25="WT001","kg",IF('RawData'!E25="WT002","ton",IF('RawData'!E25="WT003","k ton","")))) -> ton | F24: =IF(ISNUMBER(SEARCH("World",'RawData'!C25)),"",'RawData'!F25) -> 500 | G24: =IF(ISNUMBER(SEARCH("World",'RawData'!C25)),"",'RawData'!G25) -> 500 | H24: =IF(ISNUMBER(SEARCH("World",'RawData'!C25)),"",SUMIFS('RawData'!G:G,'RawData'!B:B,'RawData'!B25,'RawData'!C:C,"*World*")) -> 61000 | I24: =IF(ISNUMBER(SEARCH("World",'RawData'!C25)),"",IFERROR(G24/H24,"-")) -> 0.0081967213 | J24: =IF(ISNUMBER(SEARCH("World",'RawData'!C25)),"",IF(ISNUMBER(SEARCH("Other",C24)),COUNTIFS('RawData'!B:B,B24,'RawData'!C:C,"<>*World*"),IF(OR(G24="",G24=0),"-",SUMPRODUCT(('RawData'!B$2:B$822=B24)*('RawData'!G$2:G$822>G24)*(ISERROR(SEARCH("World",'RawData'!C$2:C$822)))*(ISERROR(SEARCH("Other",'RawData'!C$2:C$822))))+1))) -> 5 | K24: =IF(ISNUMBER(SEARCH("World",'RawData'!C25)),"",'RawData'!H25) -> 0 | L24: =IF(ISNUMBER(SEARCH("World",'RawData'!C25)),"",SUMIFS('RawData'!H:H,'RawData'!B:B,'RawData'!B25,'RawData'!C:C,"*World*")) -> 0 | M24: =IF(ISNUMBER(SEARCH("World",'RawData'!C25)),"",IFERROR(K24/L24,"-")) -> - | N24: =IF(ISNUMBER(SEARCH("World",'RawData'!C25)),"",IF(ISNUMBER(SEARCH("Other",C24)),COUNTIFS('RawData'!B:B,B24,'RawData'!C:C,"<>*World*"),IF(OR(K24="",K24=0),"-",SUMPRODUCT(('RawData'!B$2:B$822=B24)*('RawData'!H$2:H$822>K24)*(ISERROR(SEARCH("World",'RawData'!C$2:C$822)))*(ISERROR(SEARCH("Other",'RawData'!C$2:C$822))))+1))) -> -
A25: =IF(ISNUMBER(SEARCH("World",'RawData'!C26)),"",'RawData'!A26) -> MCS2026 | B25: =IF(ISNUMBER(SEARCH("World",'RawData'!C26)),"",'RawData'!B26) -> Arsenic | C25: =IF(ISNUMBER(SEARCH("World",'RawData'!C26)),"",'RawData'!C26) -> United States | D25: =IF(ISNUMBER(SEARCH("World",'RawData'!C26)),"",'RawData'!D26) -> Plant production, arsenic trioxide or calculated equivalent. | E25: =IF(ISNUMBER(SEARCH("World",'RawData'!C26)),"",IF('RawData'!E26="WT001","kg",IF('RawData'!E26="WT002","ton",IF('RawData'!E26="WT003","k ton","")))) -> ton | F25: =IF(ISNUMBER(SEARCH("World",'RawData'!C26)),"",'RawData'!F26) -> 0 | G25: =IF(ISNUMBER(SEARCH("World",'RawData'!C26)),"",'RawData'!G26) -> 0 | H25: =IF(ISNUMBER(SEARCH("World",'RawData'!C26)),"",SUMIFS('RawData'!G:G,'RawData'!B:B,'RawData'!B26,'RawData'!C:C,"*World*")) -> 61000 | I25: =IF(ISNUMBER(SEARCH("World",'RawData'!C26)),"",IFERROR(G25/H25,"-")) -> 0 | J25: =IF(ISNUMBER(SEARCH("World",'RawData'!C26)),"",IF(ISNUMBER(SEARCH("Other",C25)),COUNTIFS('RawData'!B:B,B25,'RawData'!C:C,"<>*World*"),IF(OR(G25="",G25=0),"-",SUMPRODUCT(('RawData'!B$2:B$822=B25)*('RawData'!G$2:G$822>G25)*(ISERROR(SEARCH("World",'RawData'!C$2:C$822)))*(ISERROR(SEARCH("Other",'RawData'!C$2:C$822))))+1))) -> - | K25: =IF(ISNUMBER(SEARCH("World",'RawData'!C26)),"",'RawData'!H26) -> 0 | L25: =IF(ISNUMBER(SEARCH("World",'RawData'!C26)),"",SUMIFS('RawData'!H:H,'RawData'!B:B,'RawData'!B26,'RawData'!C:C,"*World*")) -> 0 | M25: =IF(ISNUMBER(SEARCH("World",'RawData'!C26)),"",IFERROR(K25/L25,"-")) -> - | N25: =IF(ISNUMBER(SEARCH("World",'RawData'!C26)),"",IF(ISNUMBER(SEARCH("Other",C25)),COUNTIFS('RawData'!B:B,B25,'RawData'!C:C,"<>*World*"),IF(OR(K25="",K25=0),"-",SUMPRODUCT(('RawData'!B$2:B$822=B25)*('RawData'!H$2:H$822>K25)*(ISERROR(SEARCH("World",'RawData'!C$2:C$822)))*(ISERROR(SEARCH("Other",'RawData'!C$2:C$822))))+1))) -> -
A26: =IF(ISNUMBER(SEARCH("World",'RawData'!C28)),"",'RawData'!A28) -> MCS2026 | B26: =IF(ISNUMBER(SEARCH("World",'RawData'!C28)),"",'RawData'!B28) -> Asbestos | C26: =IF(ISNUMBER(SEARCH("World",'RawData'!C28)),"",'RawData'!C28) -> Brazil | D26: =IF(ISNUMBER(SEARCH("World",'RawData'!C28)),"",'RawData'!D28) -> Mine production, asbestos | E26: =IF(ISNUMBER(SEARCH("World",'RawData'!C28)),"",IF('RawData'!E28="WT001","kg",IF('RawData'!E28="WT002","ton",IF('RawData'!E28="WT003","k ton","")))) -> ton | F26: =IF(ISNUMBER(SEARCH("World",'RawData'!C28)),"",'RawData'!F28) -> 116890 | G26: =IF(ISNUMBER(SEARCH("World",'RawData'!C28)),"",'RawData'!G28) -> 150000 | H26: =IF(ISNUMBER(SEARCH("World",'RawData'!C28)),"",SUMIFS('RawData'!G:G,'RawData'!B:B,'RawData'!B28,'RawData'!C:C,"*World*")) -> 960000 | I26: =IF(ISNUMBER(SEARCH("World",'RawData'!C28)),"",IFERROR(G26/H26,"-")) -> 0.15625 | J26: =IF(ISNUMBER(SEARCH("World",'RawData'!C28)),"",IF(ISNUMBER(SEARCH("Other",C26)),COUNTIFS('RawData'!B:B,B26,'RawData'!C:C,"<>*World*"),IF(OR(G26="",G26=0),"-",SUMPRODUCT(('RawData'!B$2:B$822=B26)*('RawData'!G$2:G$822>G26)*(ISERROR(SEARCH("World",'RawData'!C$2:C$822)))*(ISERROR(SEARCH("Other",'RawData'!C$2:C$822))))+1))) -> 4 | K26: =IF(ISNUMBER(SEARCH("World",'RawData'!C28)),"",'RawData'!H28) -> 11000000 | L26: =IF(ISNUMBER(SEARCH("World",'RawData'!C28)),"",SUMIFS('RawData'!H:H,'RawData'!B:B,'RawData'!B28,'RawData'!C:C,"*World*")) -> 150000000 | M26: =IF(ISNUMBER(SEARCH("World",'RawData'!C28)),"",IFERROR(K26/L26,"-")) -> 0.073333333 | N26: =IF(ISNUMBER(SEARCH("World",'RawData'!C28)),"",IF(ISNUMBER(SEARCH("Other",C26)),COUNTIFS('RawData'!B:B,B26,'RawData'!C:C,"<>*World*"),IF(OR(K26="",K26=0),"-",SUMPRODUCT(('RawData'!B$2:B$822=B26)*('RawData'!H$2:H$822>K26)*(ISERROR(SEARCH("World",'RawData'!C$2:C$822)))*(ISERROR(SEARCH("Other",'RawData'!C$2:C$822))))+1))) -> 3
A27: =IF(ISNUMBER(SEARCH("World",'RawData'!C29)),"",'RawData'!A29) -> MCS2026 | B27: =IF(ISNUMBER(SEARCH("World",'RawData'!C29)),"",'RawData'!B29) -> Asbestos | C27: =IF(ISNUMBER(SEARCH("World",'RawData'!C29)),"",'RawData'!C29) -> China | D27: =IF(ISNUMBER(SEARCH("World",'RawData'!C29)),"",'RawData'!D29) -> Mine production, asbestos | E27: =IF(ISNUMBER(SEARCH("World",'RawData'!C29)),"",IF('RawData'!E29="WT001","kg",IF('RawData'!E29="WT002","ton",IF('RawData'!E29="WT003","k ton","")))) -> ton | F27: =IF(ISNUMBER(SEARCH("World",'RawData'!C29)),"",'RawData'!F29) -> 250000 | G27: =IF(ISNUMBER(SEARCH("World",'RawData'!C29)),"",'RawData'!G29) -> 250000 | H27: =IF(ISNUMBER(SEARCH("World",'RawData'!C29)),"",SUMIFS('RawData'!G:G,'RawData'!B:B,'RawData'!B29,'RawData'!C:C,"*World*")) -> 960000 | I27: =IF(ISNUMBER(SEARCH("World",'RawData'!C29)),"",IFERROR(G27/H27,"-")) -> 0.26041667 | J27: =IF(ISNUMBER(SEARCH("World",'RawData'!C29)),"",IF(ISNUMBER(SEARCH("Other",C27)),COUNTIFS('RawData'!B:B,B27,'RawData'!C:C,"<>*World*"),IF(OR(G27="",G27=0),"-",SUMPRODUCT(('RawData'!B$2:B$822=B27)*('RawData'!G$2:G$822>G27)*(ISERROR(SEARCH("World",'RawData'!C$2:C$822)))*(ISERROR(SEARCH("Other",'RawData'!C$2:C$822))))+1))) -> 2 | K27: =IF(ISNUMBER(SEARCH("World",'RawData'!C29)),"",'RawData'!H29) -> 7100000 | L27: =IF(ISNUMBER(SEARCH("World",'RawData'!C29)),"",SUMIFS('RawData'!H:H,'RawData'!B:B,'RawData'!B29,'RawData'!C:C,"*World*")) -> 150000000 | M27: =IF(ISNUMBER(SEARCH("World",'RawData'!C29)),"",IFERROR(K27/L27,"-")) -> 0.047333333 | N27: =IF(ISNUMBER(SEARCH("World",'RawData'!C29)),"",IF(ISNUMBER(SEARCH("Other",C27)),COUNTIFS('RawData'!B:B,B27,'RawData'!C:C,"<>*World*"),IF(OR(K27="",K27=0),"-",SUMPRODUCT(('RawData'!B$2:B$822=B27)*('RawData'!H$2:H$822>K27)*(ISERROR(SEARCH("World",'RawData'!C$2:C$822)))*(ISERROR(SEARCH("Other",'RawData'!C$2:C$822))))+1))) -> 4
A28: =IF(ISNUMBER(SEARCH("World",'RawData'!C30)),"",'RawData'!A30) -> MCS2026 | B28: =IF(ISNUMBER(SEARCH("World",'RawData'!C30)),"",'RawData'!B30) -> Asbestos | C28: =IF(ISNUMBER(SEARCH("World",'RawData'!C30)),"",'RawData'!C30) -> Kazakhstan | D28: =IF(ISNUMBER(SEARCH("World",'RawData'!C30)),"",'RawData'!D30) -> Mine production, asbestos | E28: =IF(ISNUMBER(SEARCH("World",'RawData'!C30)),"",IF('RawData'!E30="WT001","kg",IF('RawData'!E30="WT002","ton",IF('RawData'!E30="WT003","k ton","")))) -> ton | F28: =IF(ISNUMBER(SEARCH("World",'RawData'!C30)),"",'RawData'!F30) -> 225700 | G28: =IF(ISNUMBER(SEARCH("World",'RawData'!C30)),"",'RawData'!G30) -> 250000 | H28: =IF(ISNUMBER(SEARCH("World",'RawData'!C30)),"",SUMIFS('RawData'!G:G,'RawData'!B:B,'RawData'!B30,'RawData'!C:C,"*World*")) -> 960000 | I28: =IF(ISNUMBER(SEARCH("World",'RawData'!C30)),"",IFERROR(G28/H28,"-")) -> 0.26041667 | J28: =IF(ISNUMBER(SEARCH("World",'RawData'!C30)),"",IF(ISNUMBER(SEARCH("Other",C28)),COUNTIFS('RawData'!B:B,B28,'RawData'!C:C,"<>*World*"),IF(OR(G28="",G28=0),"-",SUMPRODUCT(('RawData'!B$2:B$822=B28)*('RawData'!G$2:G$822>G28)*(ISERROR(SEARCH("World",'RawData'!C$2:C$822)))*(ISERROR(SEARCH("Other",'RawData'!C$2:C$822))))+1))) -> 2 | K28: =IF(ISNUMBER(SEARCH("World",'RawData'!C30)),"",'RawData'!H30) -> 20000000 | L28: =IF(ISNUMBER(SEARCH("World",'RawData'!C30)),"",SUMIFS('RawData'!H:H,'RawData'!B:B,'RawData'!B30,'RawData'!C:C,"*World*")) -> 150000000 | M28: =IF(ISNUMBER(SEARCH("World",'RawData'!C30)),"",IFERROR(K28/L28,"-")) -> 0.13333333 | N28: =IF(ISNUMBER(SEARCH("World",'RawData'!C30)),"",IF(ISNUMBER(SEARCH("Other",C28)),COUNTIFS('RawData'!B:B,B28,'RawData'!C:C,"<>*World*"),IF(OR(K28="",K28=0),"-",SUMPRODUCT(('RawData'!B$2:B$822=B28)*('RawData'!H$2:H$822>K28)*(ISERROR(SEARCH("World",'RawData'!C$2:C$822)))*(ISERROR(SEARCH("Other",'RawData'!C$2:C$822))))+1))) -> 2
A29: =IF(ISNUMBER(SEARCH("World",'RawData'!C31)),"",'RawData'!A31) -> MCS2026 | B29: =IF(ISNUMBER(SEARCH("World",'RawData'!C31)),"",'RawData'!B31) -> Asbestos | C29: =IF(ISNUMBER(SEARCH("World",'RawData'!C31)),"",'RawData'!C31) -> Russia | D29: =IF(ISNUMBER(SEARCH("World",'RawData'!C31)),"",'RawData'!D31) -> Mine production, asbestos | E29: =IF(ISNUMBER(SEARCH("World",'RawData'!C31)),"",IF('RawData'!E31="WT001","kg",IF('RawData'!E31="WT002","ton",IF('RawData'!E31="WT003","k ton","")))) -> ton | F29: =IF(ISNUMBER(SEARCH("World",'RawData'!C31)),"",'RawData'!F31) -> 306900 | G29: =IF(ISNUMBER(SEARCH("World",'RawData'!C31)),"",'RawData'!G31) -> 310000 | H29: =IF(ISNUMBER(SEARCH("World",'RawData'!C31)),"",SUMIFS('RawData'!G:G,'RawData'!B:B,'RawData'!B31,'RawData'!C:C,"*World*")) -> 960000 | I29: =IF(ISNUMBER(SEARCH("World",'RawData'!C31)),"",IFERROR(G29/H29,"-")) -> 0.32291667 | J29: =IF(ISNUMBER(SEARCH("World",'RawData'!C31)),"",IF(ISNUMBER(SEARCH("Other",C29)),COUNTIFS('RawData'!B:B,B29,'RawData'!C:C,"<>*World*"),IF(OR(G29="",G29=0),"-",SUMPRODUCT(('RawData'!B$2:B$822=B29)*('RawData'!G$2:G$822>G29)*(ISERROR(SEARCH("World",'RawData'!C$2:C$822)))*(ISERROR(SEARCH("Other",'RawData'!C$2:C$822))))+1))) -> 1 | K29: =IF(ISNUMBER(SEARCH("World",'RawData'!C31)),"",'RawData'!H31) -> 110000000 | L29: =IF(ISNUMBER(SEARCH("World",'RawData'!C31)),"",SUMIFS('RawData'!H:H,'RawData'!B:B,'RawData'!B31,'RawData'!C:C,"*World*")) -> 150000000 | M29: =IF(ISNUMBER(SEARCH("World",'RawData'!C31)),"",IFERROR(K29/L29,"-")) -> 0.73333333 | N29: =IF(ISNUMBER(SEARCH("World",'RawData'!C31)),"",IF(ISNUMBER(SEARCH("Other",C29)),COUNTIFS('RawData'!B:B,B29,'RawData'!C:C,"<>*World*"),IF(OR(K29="",K29=0),"-",SUMPRODUCT(('RawData'!B$2:B$822=B29)*('RawData'!H$2:H$822>K29)*(ISERROR(SEARCH("World",'RawData'!C$2:C$822)))*(ISERROR(SEARCH("Other",'RawData'!C$2:C$822))))+1))) -> 1
A30: =IF(ISNUMBER(SEARCH("World",'RawData'!C32)),"",'RawData'!A32) -> MCS2026 | B30: =IF(ISNUMBER(SEARCH("World",'RawData'!C32)),"",'RawData'!B32) -> Asbestos | C30: =IF(ISNUMBER(SEARCH("World",'RawData'!C32)),"",'RawData'!C32) -> United States | D30: =IF(ISNUMBER(SEARCH("World",'RawData'!C32)),"",'RawData'!D32) -> Mine production, asbestos | E30: =IF(ISNUMBER(SEARCH("World",'RawData'!C32)),"",IF('RawData'!E32="WT001","kg",IF('RawData'!E32="WT002","ton",IF('RawData'!E32="WT003","k ton","")))) -> ton | F30: =IF(ISNUMBER(SEARCH("World",'RawData'!C32)),"",'RawData'!F32) -> 0 | G30: =IF(ISNUMBER(SEARCH("World",'RawData'!C32)),"",'RawData'!G32) -> 0 | H30: =IF(ISNUMBER(SEARCH("World",'RawData'!C32)),"",SUMIFS('RawData'!G:G,'RawData'!B:B,'RawData'!B32,'RawData'!C:C,"*World*")) -> 960000 | I30: =IF(ISNUMBER(SEARCH("World",'RawData'!C32)),"",IFERROR(G30/H30,"-")) -> 0 | J30: =IF(ISNUMBER(SEARCH("World",'RawData'!C32)),"",IF(ISNUMBER(SEARCH("Other",C30)),COUNTIFS('RawData'!B:B,B30,'RawData'!C:C,"<>*World*"),IF(OR(G30="",G30=0),"-",SUMPRODUCT(('RawData'!B$2:B$822=B30)*('RawData'!G$2:G$822>G30)*(ISERROR(SEARCH("World",'RawData'!C$2:C$822)))*(ISERROR(SEARCH("Other",'RawData'!C$2:C$822))))+1))) -> - | K30: =IF(ISNUMBER(SEARCH("World",'RawData'!C32)),"",'RawData'!H32) -> 0 | L30: =IF(ISNUMBER(SEARCH("World",'RawData'!C32)),"",SUMIFS('RawData'!H:H,'RawData'!B:B,'RawData'!B32,'RawData'!C:C,"*World*")) -> 150000000 | M30: =IF(ISNUMBER(SEARCH("World",'RawData'!C32)),"",IFERROR(K30/L30,"-")) -> 0 | N30: =IF(ISNUMBER(SEARCH("World",'RawData'!C32)),"",IF(ISNUMBER(SEARCH("Other",C30)),COUNTIFS('RawData'!B:B,B30,'RawData'!C:C,"<>*World*"),IF(OR(K30="",K30=0),"-",SUMPRODUCT(('RawData'!B$2:B$822=B30)*('RawData'!H$2:H$822>K30)*(ISERROR(SEARCH("World",'RawData'!C$2:C$822)))*(ISERROR(SEARCH("Other",'RawData'!C$2:C$822))))+1))) -> -
A31: =IF(ISNUMBER(SEARCH("World",'RawData'!C34)),"",'RawData'!A34) -> MCS2026 | B31: =IF(ISNUMBER(SEARCH("World",'RawData'!C34)),"",'RawData'!B34) -> Barite | C31: =IF(ISNUMBER(SEARCH("World",'RawData'!C34)),"",'RawData'!C34) -> China | D31: =IF(ISNUMBER(SEARCH("World",'RawData'!C34)),"",'RawData'!D34) -> Mine production, barite, estimated | E31: =IF(ISNUMBER(SEARCH("World",'RawData'!C34)),"",IF('RawData'!E34="WT001","kg",IF('RawData'!E34="WT002","ton",IF('RawData'!E34="WT003","k ton","")))) -> k ton | F31: =IF(ISNUMBER(SEARCH("World",'RawData'!C34)),"",'RawData'!F34) -> 2100 | G31: =IF(ISNUMBER(SEARCH("World",'RawData'!C34)),"",'RawData'!G34) -> 2200 | H31: =IF(ISNUMBER(SEARCH("World",'RawData'!C34)),"",SUMIFS('RawData'!G:G,'RawData'!B:B,'RawData'!B34,'RawData'!C:C,"*World*")) -> 8700 | I31: =IF(ISNUMBER(SEARCH("World",'RawData'!C34)),"",IFERROR(G31/H31,"-")) -> 0.25287356 | J31: =IF(ISNUMBER(SEARCH("World",'RawData'!C34)),"",IF(ISNUMBER(SEARCH("Other",C31)),COUNTIFS('RawData'!B:B,B31,'RawData'!C:C,"<>*World*"),IF(OR(G31="",G31=0),"-",SUMPRODUCT(('RawData'!B$2:B$822=B31)*('RawData'!G$2:G$822>G31)*(ISERROR(SEARCH("World",'RawData'!C$2:C$822)))*(ISERROR(SEARCH("Other",'RawData'!C$2:C$822))))+1))) -> 2 | K31: =IF(ISNUMBER(SEARCH("World",'RawData'!C34)),"",'RawData'!H34) -> 120000 | L31: =IF(ISNUMBER(SEARCH("World",'RawData'!C34)),"",SUMIFS('RawData'!H:H,'RawData'!B:B,'RawData'!B34,'RawData'!C:C,"*World*")) -> 0 | M31: =IF(ISNUMBER(SEARCH("World",'RawData'!C34)),"",IFERROR(K31/L31,"-")) -> - | N31: =IF(ISNUMBER(SEARCH("World",'RawData'!C34)),"",IF(ISNUMBER(SEARCH("Other",C31)),COUNTIFS('RawData'!B:B,B31,'RawData'!C:C,"<>*World*"),IF(OR(K31="",K31=0),"-",SUMPRODUCT(('RawData'!B$2:B$822=B31)*('RawData'!H$2:H$822>K31)*(ISERROR(SEARCH("World",'RawData'!C$2:C$822)))*(ISERROR(SEARCH("Other",'RawData'!C$2:C$822))))+1))) -> 1
A32: =IF(ISNUMBER(SEARCH("World",'RawData'!C35)),"",'RawData'!A35) -> MCS2026 | B32: =IF(ISNUMBER(SEARCH("World",'RawData'!C35)),"",'RawData'!B35) -> Barite | C32: =IF(ISNUMBER(SEARCH("World",'RawData'!C35)),"",'RawData'!C35) -> India | D32: =IF(ISNUMBER(SEARCH("World",'RawData'!C35)),"",'RawData'!D35) -> Mine production, barite, estimated | E32: =IF(ISNUMBER(SEARCH("World",'RawData'!C35)),"",IF('RawData'!E35="WT001","kg",IF('RawData'!E35="WT002","ton",IF('RawData'!E35="WT003","k ton","")))) -> k ton | F32: =IF(ISNUMBER(SEARCH("World",'RawData'!C35)),"",'RawData'!F35) -> 2600 | G32: =IF(ISNUMBER(SEARCH("World",'RawData'!C35)),"",'RawData'!G35) -> 3000 | H32: =IF(ISNUMBER(SEARCH("World",'RawData'!C35)),"",SUMIFS('RawData'!G:G,'RawData'!B:B,'RawData'!B35,'RawData'!C:C,"*World*")) -> 8700 | I32: =IF(ISNUMBER(SEARCH("World",'RawData'!C35)),"",IFERROR(G32/H32,"-")) -> 0.34482759 | J32: =IF(ISNUMBER(SEARCH("World",'RawData'!C35)),"",IF(ISNUMBER(SEARCH("Other",C32)),COUNTIFS('RawData'!B:B,B32,'RawData'!C:C,"<>*World*"),IF(OR(G32="",G32=0),"-",SUMPRODUCT(('RawData'!B$2:B$822=B32)*('RawData'!G$2:G$822>G32)*(ISERROR(SEARCH("World",'RawData'!C$2:C$822)))*(ISERROR(SEARCH("Other",'RawData'!C$2:C$822))))+1))) -> 1 | K32: =IF(ISNUMBER(SEARCH("World",'RawData'!C35)),"",'RawData'!H35) -> 51000 | L32: =IF(ISNUMBER(SEARCH("World",'RawData'!C35)),"",SUMIFS('RawData'!H:H,'RawData'!B:B,'RawData'!B35,'RawData'!C:C,"*World*")) -> 0 | M32: =IF(ISNUMBER(SEARCH("World",'RawData'!C35)),"",IFERROR(K32/L32,"-")) -> - | N32: =IF(ISNUMBER(SEARCH("World",'RawData'!C35)),"",IF(ISNUMBER(SEARCH("Other",C32)),COUNTIFS('RawData'!B:B,B32,'RawData'!C:C,"<>*World*"),IF(OR(K32="",K32=0),"-",SUMPRODUCT(('RawData'!B$2:B$822=B32)*('RawData'!H$2:H$822>K32)*(ISERROR(SEARCH("World",'RawData'!C$2:C$822)))*(ISERROR(SEARCH("Other",'RawData'!C$2:C$822))))+1))) -> 4
A33: =IF(ISNUMBER(SEARCH("World",'RawData'!C36)),"",'RawData'!A36) -> MCS2026 | B33: =IF(ISNUMBER(SEARCH("World",'RawData'!C36)),"",'RawData'!B36) -> Barite | C33: =IF(ISNUMBER(SEARCH("World",'RawData'!C36)),"",'RawData'!C36) -> Iran | D33: =IF(ISNUMBER(SEARCH("World",'RawData'!C36)),"",'RawData'!D36) -> Mine production, barite, estimated | E33: =IF(ISNUMBER(SEARCH("World",'RawData'!C36)),"",IF('RawData'!E36="WT001","kg",IF('RawData'!E36="WT002","ton",IF('RawData'!E36="WT003","k ton","")))) -> k ton | F33: =IF(ISNUMBER(SEARCH("World",'RawData'!C36)),"",'RawData'!F36) -> 300 | G33: =IF(ISNUMBER(SEARCH("World",'RawData'!C36)),"",'RawData'!G36) -> 300 | H33: =IF(ISNUMBER(SEARCH("World",'RawData'!C36)),"",SUMIFS('RawData'!G:G,'RawData'!B:B,'RawData'!B36,'RawData'!C:C,"*World*")) -> 8700 | I33: =IF(ISNUMBER(SEARCH("World",'RawData'!C36)),"",IFERROR(G33/H33,"-")) -> 0.034482759 | J33: =IF(ISNUMBER(SEARCH("World",'RawData'!C36)),"",IF(ISNUMBER(SEARCH("Other",C33)),COUNTIFS('RawData'!B:B,B33,'RawData'!C:C,"<>*World*"),IF(OR(G33="",G33=0),"-",SUMPRODUCT(('RawData'!B$2:B$822=B33)*('RawData'!G$2:G$822>G33)*(ISERROR(SEARCH("World",'RawData'!C$2:C$822)))*(ISERROR(SEARCH("Other",'RawData'!C$2:C$822))))+1))) -> 5 | K33: =IF(ISNUMBER(SEARCH("World",'RawData'!C36)),"",'RawData'!H36) -> 100000 | L33: =IF(ISNUMBER(SEARCH("World",'RawData'!C36)),"",SUMIFS('RawData'!H:H,'RawData'!B:B,'RawData'!B36,'RawData'!C:C,"*World*")) -> 0 | M33: =IF(ISNUMBER(SEARCH("World",'RawData'!C36)),"",IFERROR(K33/L33,"-")) -> - | N33: =IF(ISNUMBER(SEARCH("World",'RawData'!C36)),"",IF(ISNUMBER(SEARCH("Other",C33)),COUNTIFS('RawData'!B:B,B33,'RawData'!C:C,"<>*World*"),IF(OR(K33="",K33=0),"-",SUMPRODUCT(('RawData'!B$2:B$822=B33)*('RawData'!H$2:H$822>K33)*(ISERROR(SEARCH("World",'RawData'!C$2:C$822)))*(ISERROR(SEARCH("Other",'RawData'!C$2:C$822))))+1))) -> 2
A34: =IF(ISNUMBER(SEARCH("World",'RawData'!C37)),"",'RawData'!A37) -> MCS2026 | B34: =IF(ISNUMBER(SEARCH("World",'RawData'!C37)),"",'RawData'!B37) -> Barite | C34: =IF(ISNUMBER(SEARCH("World",'RawData'!C37)),"",'RawData'!C37) -> Kazakhstan | D34: =IF(ISNUMBER(SEARCH("World",'RawData'!C37)),"",'RawData'!D37) -> Mine production, barite, estimated | E34: =IF(ISNUMBER(SEARCH("World",'RawData'!C37)),"",IF('RawData'!E37="WT001","kg",IF('RawData'!E37="WT002","ton",IF('RawData'!E37="WT003","k ton","")))) -> k ton | F34: =IF(ISNUMBER(SEARCH("World",'RawData'!C37)),"",'RawData'!F37) -> 650 | G34: =IF(ISNUMBER(SEARCH("World",'RawData'!C37)),"",'RawData'!G37) -> 700 | H34: =IF(ISNUMBER(SEARCH("World",'RawData'!C37)),"",SUMIFS('RawData'!G:G,'RawData'!B:B,'RawData'!B37,'RawData'!C:C,"*World*")) -> 8700 | I34: =IF(ISNUMBER(SEARCH("World",'RawData'!C37)),"",IFERROR(G34/H34,"-")) -> 0.08045977 | J34: =IF(ISNUMBER(SEARCH("World",'RawData'!C37)),"",IF(ISNUMBER(SEARCH("Other",C34)),COUNTIFS('RawData'!B:B,B34,'RawData'!C:C,"<>*World*"),IF(OR(G34="",G34=0),"-",SUMPRODUCT(('RawData'!B$2:B$822=B34)*('RawData'!G$2:G$822>G34)*(ISERROR(SEARCH("World",'RawData'!C$2:C$822)))*(ISERROR(SEARCH("Other",'RawData'!C$2:C$822))))+1))) -> 4 | K34: =IF(ISNUMBER(SEARCH("World",'RawData'!C37)),"",'RawData'!H37) -> 85000 | L34: =IF(ISNUMBER(SEARCH("World",'RawData'!C37)),"",SUMIFS('RawData'!H:H,'RawData'!B:B,'RawData'!B37,'RawData'!C:C,"*World*")) -> 0 | M34: =IF(ISNUMBER(SEARCH("World",'RawData'!C37)),"",IFERROR(K34/L34,"-")) -> - | N34: =IF(ISNUMBER(SEARCH("World",'RawData'!C37)),"",IF(ISNUMBER(SEARCH("Other",C34)),COUNTIFS('RawData'!B:B,B34,'RawData'!C:C,"<>*World*"),IF(OR(K34="",K34=0),"-",SUMPRODUCT(('RawData'!B$2:B$822=B34)*('RawData'!H$2:H$822>K34)*(ISERROR(SEARCH("World",'RawData'!C$2:C$822)))*(ISERROR(SEARCH("Other",'RawData'!C$2:C$822))))+1))) -> 3
